<?xml version="1.0" encoding="UTF-8"?>
<testng-results skipped="0" failed="1" total="3" passed="2">
  <reporter-output>
  </reporter-output>
  <suite name="Default suite" duration-ms="137623" started-at="2017-03-27T16:37:15Z" finished-at="2017-03-27T16:39:33Z">
    <groups>
    </groups>
    <test name="Default test" duration-ms="137623" started-at="2017-03-27T16:37:15Z" finished-at="2017-03-27T16:39:33Z">
      <class name="com.vh.ui.tests.LoginTest">
        <test-method status="PASS" signature="verify_InvalidPassword()[pri:0, instance:com.vh.ui.tests.LoginTest@4232b34a]" name="verify_InvalidPassword" duration-ms="44680" started-at="2017-03-27T11:37:15Z" finished-at="2017-03-27T11:38:00Z">
          <reporter-output>
          </reporter-output>
        </test-method> <!-- verify_InvalidPassword -->
        <test-method status="PASS" signature="afterTest(java.lang.reflect.Method, org.testng.ITestResult)[pri:0, instance:com.vh.ui.tests.LoginTest@4232b34a]" name="afterTest" is-config="true" duration-ms="7" started-at="2017-03-27T11:38:00Z" finished-at="2017-03-27T11:38:00Z">
          <params>
            <param index="0">
              <value>
                <![CDATA[public void com.vh.ui.tests.LoginTest.verify_InvalidPassword() throws com.vh.ui.exceptions.WaitException,com.vh.ui.exceptions.URLNavigationException,java.lang.InterruptedException]]>
              </value>
            </param>
            <param index="1">
              <value>
                <![CDATA[[TestResult name=verify_InvalidPassword status=SUCCESS method=LoginTest.verify_InvalidPassword()[pri:0, instance:com.vh.ui.tests.LoginTest@4232b34a] output={null}]]]>
              </value>
            </param>
          </params>
          <reporter-output>
          </reporter-output>
        </test-method> <!-- afterTest -->
        <test-method status="PASS" signature="verify_InvalidUserName()[pri:0, instance:com.vh.ui.tests.LoginTest@4232b34a]" name="verify_InvalidUserName" duration-ms="21670" started-at="2017-03-27T11:38:00Z" finished-at="2017-03-27T11:38:21Z">
          <reporter-output>
          </reporter-output>
        </test-method> <!-- verify_InvalidUserName -->
        <test-method status="PASS" signature="afterTest(java.lang.reflect.Method, org.testng.ITestResult)[pri:0, instance:com.vh.ui.tests.LoginTest@4232b34a]" name="afterTest" is-config="true" duration-ms="0" started-at="2017-03-27T11:38:21Z" finished-at="2017-03-27T11:38:21Z">
          <params>
            <param index="0">
              <value>
                <![CDATA[public void com.vh.ui.tests.LoginTest.verify_InvalidUserName() throws com.vh.ui.exceptions.WaitException,com.vh.ui.exceptions.URLNavigationException,java.lang.InterruptedException]]>
              </value>
            </param>
            <param index="1">
              <value>
                <![CDATA[[TestResult name=verify_InvalidUserName status=SUCCESS method=LoginTest.verify_InvalidUserName()[pri:0, instance:com.vh.ui.tests.LoginTest@4232b34a] output={null}]]]>
              </value>
            </param>
          </params>
          <reporter-output>
          </reporter-output>
        </test-method> <!-- afterTest -->
        <test-method status="FAIL" signature="verify_SuccessfulLogin()[pri:0, instance:com.vh.ui.tests.LoginTest@4232b34a]" name="verify_SuccessfulLogin" duration-ms="65716" started-at="2017-03-27T11:38:21Z" finished-at="2017-03-27T11:39:27Z">
          <exception class="java.lang.AssertionError">
            <message>
              <![CDATA[Failed to identify Yes, Allow button expected [true] but found [false]]]>
            </message>
            <full-stacktrace>
              <![CDATA[java.lang.AssertionError: Failed to identify Yes, Allow button expected [true] but found [false]
	at org.testng.Assert.fail(Assert.java:94)
	at org.testng.Assert.failNotEquals(Assert.java:513)
	at org.testng.Assert.assertTrue(Assert.java:42)
	at com.vh.ui.tests.LoginTest.verify_SuccessfulLogin(LoginTest.java:82)
	at sun.reflect.NativeMethodAccessorImpl.invoke0(Native Method)
	at sun.reflect.NativeMethodAccessorImpl.invoke(Unknown Source)
	at sun.reflect.DelegatingMethodAccessorImpl.invoke(Unknown Source)
	at java.lang.reflect.Method.invoke(Unknown Source)
	at org.testng.internal.MethodInvocationHelper.invokeMethod(MethodInvocationHelper.java:86)
	at org.testng.internal.Invoker.invokeMethod(Invoker.java:643)
	at org.testng.internal.Invoker.invokeTestMethod(Invoker.java:820)
	at org.testng.internal.Invoker.invokeTestMethods(Invoker.java:1128)
	at org.testng.internal.TestMethodWorker.invokeTestMethods(TestMethodWorker.java:129)
	at org.testng.internal.TestMethodWorker.run(TestMethodWorker.java:112)
	at org.testng.TestRunner.privateRun(TestRunner.java:782)
	at org.testng.TestRunner.run(TestRunner.java:632)
	at org.testng.SuiteRunner.runTest(SuiteRunner.java:366)
	at org.testng.SuiteRunner.runSequentially(SuiteRunner.java:361)
	at org.testng.SuiteRunner.privateRun(SuiteRunner.java:319)
	at org.testng.SuiteRunner.run(SuiteRunner.java:268)
	at org.testng.SuiteRunnerWorker.runSuite(SuiteRunnerWorker.java:52)
	at org.testng.SuiteRunnerWorker.run(SuiteRunnerWorker.java:86)
	at org.testng.TestNG.runSuitesSequentially(TestNG.java:1244)
	at org.testng.TestNG.runSuitesLocally(TestNG.java:1169)
	at org.testng.TestNG.run(TestNG.java:1064)
	at org.testng.remote.AbstractRemoteTestNG.run(AbstractRemoteTestNG.java:132)
	at org.testng.remote.RemoteTestNG.initAndRun(RemoteTestNG.java:230)
	at org.testng.remote.RemoteTestNG.main(RemoteTestNG.java:76)
]]>
            </full-stacktrace>
          </exception> <!-- java.lang.AssertionError -->
          <reporter-output>
          </reporter-output>
        </test-method> <!-- verify_SuccessfulLogin -->
        <test-method status="PASS" signature="afterTest(java.lang.reflect.Method, org.testng.ITestResult)[pri:0, instance:com.vh.ui.tests.LoginTest@4232b34a]" name="afterTest" is-config="true" duration-ms="5392" started-at="2017-03-27T11:39:27Z" finished-at="2017-03-27T11:39:33Z">
          <params>
            <param index="0">
              <value>
                <![CDATA[public void com.vh.ui.tests.LoginTest.verify_SuccessfulLogin() throws com.vh.ui.exceptions.WaitException,com.vh.ui.exceptions.URLNavigationException,java.lang.InterruptedException]]>
              </value>
            </param>
            <param index="1">
              <value>
                <![CDATA[[TestResult name=verify_SuccessfulLogin status=FAILURE method=LoginTest.verify_SuccessfulLogin()[pri:0, instance:com.vh.ui.tests.LoginTest@4232b34a] output={null}]]]>
              </value>
            </param>
          </params>
          <reporter-output>
          </reporter-output>
        </test-method> <!-- afterTest -->
        <test-method status="FAIL" signature="tearDown()[pri:0, instance:com.vh.ui.tests.LoginTest@4232b34a]" name="tearDown" is-config="true" duration-ms="0" started-at="2017-03-27T11:39:33Z" finished-at="2017-03-27T11:39:33Z">
          <exception class="java.lang.NullPointerException">
            <full-stacktrace>
              <![CDATA[java.lang.NullPointerException
	at com.vh.ui.tests.LoginTest.tearDown(LoginTest.java:92)
	at sun.reflect.NativeMethodAccessorImpl.invoke0(Native Method)
	at sun.reflect.NativeMethodAccessorImpl.invoke(Unknown Source)
	at sun.reflect.DelegatingMethodAccessorImpl.invoke(Unknown Source)
	at java.lang.reflect.Method.invoke(Unknown Source)
	at org.testng.internal.MethodInvocationHelper.invokeMethod(MethodInvocationHelper.java:86)
	at org.testng.internal.Invoker.invokeConfigurationMethod(Invoker.java:514)
	at org.testng.internal.Invoker.invokeConfigurations(Invoker.java:215)
	at org.testng.internal.Invoker.invokeConfigurations(Invoker.java:142)
	at org.testng.internal.TestMethodWorker.invokeAfterClassMethods(TestMethodWorker.java:232)
	at org.testng.internal.TestMethodWorker.run(TestMethodWorker.java:115)
	at org.testng.TestRunner.privateRun(TestRunner.java:782)
	at org.testng.TestRunner.run(TestRunner.java:632)
	at org.testng.SuiteRunner.runTest(SuiteRunner.java:366)
	at org.testng.SuiteRunner.runSequentially(SuiteRunner.java:361)
	at org.testng.SuiteRunner.privateRun(SuiteRunner.java:319)
	at org.testng.SuiteRunner.run(SuiteRunner.java:268)
	at org.testng.SuiteRunnerWorker.runSuite(SuiteRunnerWorker.java:52)
	at org.testng.SuiteRunnerWorker.run(SuiteRunnerWorker.java:86)
	at org.testng.TestNG.runSuitesSequentially(TestNG.java:1244)
	at org.testng.TestNG.runSuitesLocally(TestNG.java:1169)
	at org.testng.TestNG.run(TestNG.java:1064)
	at org.testng.remote.AbstractRemoteTestNG.run(AbstractRemoteTestNG.java:132)
	at org.testng.remote.RemoteTestNG.initAndRun(RemoteTestNG.java:230)
	at org.testng.remote.RemoteTestNG.main(RemoteTestNG.java:76)
]]>
            </full-stacktrace>
          </exception> <!-- java.lang.NullPointerException -->
          <reporter-output>
          </reporter-output>
        </test-method> <!-- tearDown -->
      </class> <!-- com.vh.ui.tests.LoginTest -->
    </test> <!-- Default test -->
  </suite> <!-- Default suite -->
</testng-results>
